<?xml version="1.0"?>
<robot name="3dof">

  <link name="base">
    <inertial>
      <origin xyz="0 0 0" rpy="0 0 0"/>
       <mass value="0"/>
       <inertia ixx="0" ixy="0" ixz="0" iyy="0" iyz="0" izz="0"/>
    </inertial>
  </link>

  <link name="link1">
    <inertial>
      <origin xyz="0.5 0 0" rpy="0 0 0"/>
       <mass value="0.5"/>
       <inertia ixx="0.1" ixy="0" ixz="0" iyy="0.1" iyz="0" izz="0.1"/>
    </inertial>
    <visual>
      <origin xyz="0.5 0 0" rpy="0 0 0"/>
      <geometry>
        <box size="0.1 0.1 1.0"/>
      </geometry>
      <material name="green">
        <color rgba="0 1 0 1"/>
      </material>
    </visual>
  </link>

  <link name="link2">
    <inertial>
      <origin xyz="0.5 0 0" rpy="0 0 0"/>
       <mass value="0.5"/>
       <inertia ixx="0.1" ixy="0" ixz="0" iyy="0.1" iyz="0" izz="0.1"/>
    </inertial>
    <visual>
      <origin xyz="0 0 0.5" rpy="0 0 0"/>
      <geometry>
        <box size=" 0.1 0.1 1.0"/>
      </geometry>
      <material name="blue">
        <color rgba="0 0 1 1"/>
      </material>
    </visual>
  </link>

   <link name="link3">
    <inertial>
      <origin xyz="0.5 0 0" rpy="0 0 0"/>
       <mass value="0.5"/>
       <inertia ixx="0.1" ixy="0" ixz="0" iyy="0.1" iyz="0" izz="0.1"/>
    </inertial>
    <visual>
      <origin xyz="0 0 0.5" rpy="0 0 0"/>
      <geometry>
        <box size=" 0.1 0.1 1.0"/>
      </geometry>
      <material name="red">
        <color rgba="1 0 0 1"/>
      </material>
    </visual>
  </link>

   <link name="ee">
	<inertial>
      <origin xyz="0 0 0" rpy="0 0 0"/>
       <mass value="0"/>
       <inertia ixx="0" ixy="0" ixz="0" iyy="0" iyz="0" izz="0"/>
    </inertial>
  </link>



  <joint name="joint1" type="revolute">
    <parent link="base" />
    <child link="link1" />
    <limit effort="30" velocity="1.0" lower="-3.1415926535" upper="3.1415926535" />
    <origin xyz="0 0 0" rpy="0 0 0" />
    <axis xyz="0 0 1" />
  </joint>

  <joint name="joint2" type="revolute">
    <parent link="link1" />
    <child link="link2" />
    <limit effort="30" velocity="1.0" lower="-3.1415926535" upper="3.1415926535" />
    <origin xyz="1 0 0" rpy="0 0 0 " />
    <axis xyz="0 0 1" />
  </joint>

  <joint name="joint3" type="revolute">
    <parent link="link2" />
    <child link="link3" />
    <limit effort="30" velocity="1.0" lower="-3.1415926535" upper="3.1415926535" />
    <origin xyz="1 0 0" rpy="0 0 0" />
    <axis xyz="0 0 1" />
  </joint>

  <joint name="joint4" type="fixed">
    <parent link="link3" />
    <child link="ee" />
    <origin xyz="1 0 0" rpy="0 0 0" />
    <axis xyz="0 0 1" />
  </joint>


</robot>

